Workbook
Name ProductosLista: OFFSET([1]Inventario!$Q$3,0,0,COUNTA([1]Inventario!$B$3:$B$61),1)

Sheet Inventario
A1: INVENTARIO TIENDA UCN
A2: PRODUCTO | B2: COLOR | C2: TALLA | D2: PRECIO IVA | E2: PRECIO TAC | F2: STOCK ACTUAL | G2: SKU
A3: POLERON | B3: NEGRO | C3: S | D3: 24990 | E3: 21000 | F3: 0 | G3: POL-TN-S
A4: POLERON | B4: NEGRO | C4: M | D4: 24990 | E4: 21000 | F4: 2 | G4: POL-TN-M
A5: POLERON | B5: NEGRO | C5: L | D5: 24990 | E5: 21000 | F5: 19 | G5: POL-TN-L
A6: POLERON | B6: NEGRO | C6: XL | D6: 24990 | E6: 21000 | F6: 6 | G6: POL-TN-XL
A7: POLERON | B7: NEGRO | C7: XXL | D7: 24990 | E7: 21000 | F7: 0 | G7: POL-TN-XXL
A8: POLERON | B8: AZUL | C8: S | D8: 24990 | E8: 21000 | F8: 0 | G8: POL-TA-S
A9: POLERON | B9: AZUL | C9: M | D9: 24990 | E9: 21000 | F9: 1 | G9: POL-TA-M
A10: POLERON | B10: AZUL | C10: L | D10: 24990 | E10: 21000 | F10: 18 | G10: POL-TA-L
A11: POLERON | B11: AZUL | C11: XL | D11: 24990 | E11: 21000 | F11: 5 | G11: POL-TA-XL
A12: POLERON | B12: AZUL | C12: XXL | D12: 24990 | E12: 21000 | F12: 0 | G12: POL-TA-XXL
A13: LAPIZ DE COBRE | D13: 16000 | E13: 15000 | F13: 24 | G13: LAPIZ-COBRE-UNI
A14: LIBRETAS | D14: 5950 | E14: 5000 | F14: 45 | G14: LIBRETA-UCN-UNI
A15: TOTE BAG | D15: 6950 | E15: 6000 | F15: 16 | G15: TOTE-BAG-UCN-UNI
A16: LLAVERO UCENIN | D16: 5950 | E16: 5000 | F16: 53 | G16: LLAVERO-UCENIN-UNI
A17: PELUCHE | B17: ROSA | D17: 12000 | E17: 10085 | F17: 1 | G17: PELUCHE-UCN-ROSA
A18: LLAVERO TORTUGA | B18: VERDE | D18: 2500 | E18: 2500 | F18: 5 | G18: TORTUGA-VERDE
A19: LLAVERO TORTUGA | B19: AMARILLO | D19: 2500 | E19: 2500 | F19: 0 | G19: TORTUGA-AMARILLO
A20: LLAVERO ESTRELLA | B20: AMARILLO | D20: 2500 | E20: 2500 | F20: 0 | G20: ESTRELLA-AMARILLO
A21: LLAVERO ESTRELLA | B21: ROSA | D21: 2500 | E21: 2500 | F21: 8 | G21: ESTRELLA-ROSA
A22: LLAVERO CANGREJO | B22: ROJO | D22: 2500 | E22: 2500 | F22: 3 | G22: CANGREJO-ROJO
A23: LLAVERO SOLDEMAR | B23: NEGRO | D23: 2500 | E23: 2500 | F23: 7 | G23: SOLDEMAR-NEGRO
A24: LLAVERO PEZ BALLESTA | B24: NEGRO | D24: 2500 | E24: 2500 | F24: 8 | G24: PEZ-BALLESTA-NEGRO
A25: LLAVERO GAVIOTA | B25: NEGRO | D25: 2500 | E25: 2500 | F25: 9 | G25: GAVIOTA-NEGRO
A26: LLAVERO CACHALOTE | B26: NEGRO | D26: 2500 | E26: 2500 | F26: 10 | G26: CACHALOTE-NEGRO
A27: LLAVERO CANGREJO ERMITAÑO | B27: NEGRO | D27: 2500 | E27: 2500 | F27: 5 | G27: CANGREJO-ERMITANO-NEGRO
A28: LLAVERO PINGÜINO | B28: NEGRO | D28: 2500 | E28: 2500 | F28: 5 | G28: PINGUINO-NEGRO
A29: LLAVERO TIBURON | B29: NEGRO | D29: 2500 | E29: 2500 | F29: 4 | G29: TIBURON-NEGRO

Sheet Registro de ventas
A1: REGISTRO DE VENTAS
A2: ID | B2: FECHA | C2: PRODUCTO (SKU) | D2: CANTIDAD | E2: TOTAL
A3: 1 | B3: 46035 | C3: LIBRETA-UCN-UNI | D3: 1 | E3: =D3 * _xlfn.XLOOKUP(C3, Inventario!G:G, Inventario!D:D, 0) -> 5950
A4: 2 | B4: 46035 | C4: POL-TN-M | D4: 1 | E4: =D4 * _xlfn.XLOOKUP(C4, Inventario!G:G, Inventario!D:D, 0) -> 24990
A5: 2 | B5: 46035 | C5: LAPIZ-COBRE-UNI | D5: 1 | E5: =D5 * _xlfn.XLOOKUP(C5, Inventario!G:G, Inventario!D:D, 0) -> 16000
A6: 3 | B6: 46035 | C6: LLAVERO-UCENIN-UNI | D6: 1 | E6: =D6 * _xlfn.XLOOKUP(C6, Inventario!G:G, Inventario!D:D, 0) -> 5950
A7: 4 | B7: 46035 | C7: LAPIZ-COBRE-UNI | D7: 1 | E7: =D7 * _xlfn.XLOOKUP(C7, Inventario!G:G, Inventario!D:D, 0) -> 16000
A8: 5 | B8: 46035 | C8: POL-TN-L | D8: 1 | E8: =D8 * _xlfn.XLOOKUP(C8, Inventario!G:G, Inventario!D:D, 0) -> 24990
A9: 5 | B9: 46035 | C9: POL-TN-L | D9: 1 | E9: =D9 * _xlfn.XLOOKUP(C9, Inventario!G:G, Inventario!D:D, 0) -> 24990
A10: 5 | B10: 46035 | C10: LLAVERO-UCENIN-UNI | D10: 1 | E10: =D10 * _xlfn.XLOOKUP(C10, Inventario!G:G, Inventario!D:D, 0) -> 5950
A11: 6 | B11: 46035 | C11: POL-TN-L | D11: 1 | E11: =D11 * _xlfn.XLOOKUP(C11, Inventario!G:G, Inventario!D:D, 0) -> 24990
A12: 7 | B12: 46035 | C12: POL-TN-L | D12: 1 | E12: =D12 * _xlfn.XLOOKUP(C12, Inventario!G:G, Inventario!D:D, 0) -> 24990
A13: 8 | B13: 46035 | C13: LLAVERO-UCENIN-UNI | D13: 1 | E13: =D13 * _xlfn.XLOOKUP(C13, Inventario!G:G, Inventario!D:D, 0) -> 5950
A14: 9 | B14: 46035 | C14: LLAVERO-UCENIN-UNI | D14: 1 | E14: =D14 * _xlfn.XLOOKUP(C14, Inventario!G:G, Inventario!D:D, 0) -> 5950
A15: 10 | B15: 45670 | C15: LLAVERO-UCENIN-UNI | D15: 1 | E15: =D15 * _xlfn.XLOOKUP(C15, Inventario!G:G, Inventario!D:D, 0) -> 5950
C16: LAPIZ-COBRE-UNI | D16: 1 | E16: =D16 * _xlfn.XLOOKUP(C16, Inventario!G:G, Inventario!D:D, 0) -> 16000
A17: 11 | B17: 45670 | C17: LLAVERO-UCENIN-UNI | D17: 1 | E17: =D17 * _xlfn.XLOOKUP(C17, Inventario!G:G, Inventario!D:D, 0) -> 5950
A18: 12 | B18: 45670 | C18: LLAVERO-UCENIN-UNI | D18: 1 | E18: =D18 * _xlfn.XLOOKUP(C18, Inventario!G:G, Inventario!D:D, 0) -> 5950
A19: 13 | B19: 45670 | C19: LLAVERO-UCENIN-UNI | D19: 1 | E19: =D19 * _xlfn.XLOOKUP(C19, Inventario!G:G, Inventario!D:D, 0) -> 5950
C20: LAPIZ-COBRE-UNI | D20: 1 | E20: =D20 * _xlfn.XLOOKUP(C20, Inventario!G:G, Inventario!D:D, 0) -> 16000
A21: 14 | B21: 45670 | C21: LLAVERO-UCENIN-UNI | D21: 1 | E21: =D21 * _xlfn.XLOOKUP(C21, Inventario!G:G, Inventario!D:D, 0) -> 5950
A22: 15 | B22: 45670 | C22: LLAVERO-UCENIN-UNI | D22: 1 | E22: =D22 * _xlfn.XLOOKUP(C22, Inventario!G:G, Inventario!D:D, 0) -> 5950
A23: 16 | B23: 45670 | C23: LIBRETA-UCN-UNI | D23: 1 | E23: =D23 * _xlfn.XLOOKUP(C23, Inventario!G:G, Inventario!D:D, 0) -> 5950
C24: LLAVERO-UCENIN-UNI | D24: 1 | E24: =D24 * _xlfn.XLOOKUP(C24, Inventario!G:G, Inventario!D:D, 0) -> 5950
A25: 17 | B25: 45670 | C25: TOTE-BAG-UCN-UNI | D25: 1 | E25: =D25 * _xlfn.XLOOKUP(C25, Inventario!G:G, Inventario!D:D, 0) -> 6950
A26: 18 | B26: 45670 | C26: LAPIZ-COBRE-UNI | D26: 1 | E26: =D26 * _xlfn.XLOOKUP(C26, Inventario!G:G, Inventario!D:D, 0) -> 16000
A27: 19 | B27: 45670 | C27: POL-TN-XL | D27: 1 | E27: =D27 * _xlfn.XLOOKUP(C27, Inventario!G:G, Inventario!D:D, 0) -> 24990
B28: 45670 | C28: POL-TA-M | D28: 1 | E28: =D28 * _xlfn.XLOOKUP(C28, Inventario!G:G, Inventario!D:D, 0) -> 24990
A29: 19.642857 | B29: 46036 | C29: LLAVERO-UCENIN-UNI | D29: 1 | E29: =D29 * _xlfn.XLOOKUP(C29, Inventario!G:G, Inventario!D:D, 0) -> 5950
A30: 21 | B30: 46036 | C30: LLAVERO-UCENIN-UNI | D30: 1 | E30: =D30 * _xlfn.XLOOKUP(C30, Inventario!G:G, Inventario!D:D, 0) -> 5950
B31: 46036 | C31: LAPIZ-COBRE-UNI | D31: 2 | E31: =D31 * _xlfn.XLOOKUP(C31, Inventario!G:G, Inventario!D:D, 0) -> 32000
A32: 22 | B32: 46036 | C32: LLAVERO-UCENIN-UNI | D32: 1 | E32: =D32 * _xlfn.XLOOKUP(C32, Inventario!G:G, Inventario!D:D, 0) -> 5950
A33: 23 | B33: 46036 | C33: LAPIZ-COBRE-UNI | D33: 1 | E33: =D33 * _xlfn.XLOOKUP(C33, Inventario!G:G, Inventario!D:D, 0) -> 16000
A34: 24 | B34: 46037 | C34: POL-TN-L | D34: 1 | E34: =D34 * _xlfn.XLOOKUP(C34, Inventario!G:G, Inventario!D:D, 0) -> 24990
C35: LAPIZ-COBRE-UNI | D35: 1 | E35: =D35 * _xlfn.XLOOKUP(C35, Inventario!G:G, Inventario!D:D, 0) -> 16000
A36: 25 | B36: 46037 | C36: TOTE-BAG-UCN-UNI | D36: 1 | E36: =D36 * _xlfn.XLOOKUP(C36, Inventario!G:G, Inventario!D:D, 0) -> 6950
A37: 26 | B37: 46037 | C37: TOTE-BAG-UCN-UNI | D37: 1 | E37: =D37 * _xlfn.XLOOKUP(C37, Inventario!G:G, Inventario!D:D, 0) -> 6950
C38: LAPIZ-COBRE-UNI | D38: 1 | E38: =D38 * _xlfn.XLOOKUP(C38, Inventario!G:G, Inventario!D:D, 0) -> 16000
C39: LIBRETA-UCN-UNI | D39: 1 | E39: =D39 * _xlfn.XLOOKUP(C39, Inventario!G:G, Inventario!D:D, 0) -> 5950
A40: 27 | B40: 46037 | C40: LAPIZ-COBRE-UNI | D40: 1 | E40: =D40 * _xlfn.XLOOKUP(C40, Inventario!G:G, Inventario!D:D, 0) -> 16000
...

Sheet CONTROL TAC
A1: CONTROL DOCUMENTOS TAC
A2: N° TAC | B2: FECHA | C2: PRODUCTO | D2: CANTIDAD | E2: TOTAL | F2: FIRMA COMPRADOR | G2: FIRMA VENDEDOR | H2: RESPONSABLE
A3: 1 | B3: 46031 | C3: LLAVERO-UCENIN-UNI | D3: 15 | E3: =D3 * VLOOKUP(C3, CHOOSE({1,2}, Inventario!G:G, Inventario!E:E), 2, FALSE) -> 75000 | F3: Firmado | G3: Firmado | H3: PAULA CAVIERES
A4: 2 | B4: 46034 | C4: LLAVERO-UCENIN-UNI | D4: 10 | E4: =D4 * VLOOKUP(C4, CHOOSE({1,2}, Inventario!G:G, Inventario!E:E), 2, FALSE) -> 50000 | F4: Firmado | G4: Firmado | H4: CAROLINA SALINAS
A5: 3 | B5: 46100 | C5: LIBRETA-UCN-UNI | D5: 3 | E5: =D5 * VLOOKUP(C5, CHOOSE({1,2}, Inventario!G:G, Inventario!E:E), 2, FALSE) -> 15000 | F5: Firmado | G5: Firmado | H5: CARLOS SOZA
A6: 3 | B6: 46100 | C6: LAPIZ-COBRE-UNI | D6: 3 | E6: =D6 * VLOOKUP(C6, CHOOSE({1,2}, Inventario!G:G, Inventario!E:E), 2, FALSE) -> 45000 | F6: Firmado | G6: Firmado | H6: CARLOS SOZA
A7: 4 | B7: 46100 | C7: PELUCHE-UCN-ROSA | D7: 19 | E7: =D7 * VLOOKUP(C7, CHOOSE({1,2}, Inventario!G:G, Inventario!E:E), 2, FALSE) -> 191615 | F7: Pendiente | G7: Pendiente | H7: GABRIELA LLEWELLYN
A8: 5 | B8: 46154 | C8: PELUCHE-UCN-ROSA | D8: 2 | E8: =D8 * VLOOKUP(C8, CHOOSE({1,2}, Inventario!G:G, Inventario!E:E), 2, FALSE) -> 20170 | F8: Firmado | G8: Firmado | H8: ALEJANDRA VEGA
A9: 7 | B9: 46171 | C9: LAPIZ-COBRE-UNI | D9: 1 | E9: =D9 * VLOOKUP(C9, CHOOSE({1,2}, Inventario!G:G, Inventario!E:E), 2, FALSE) -> 15000 | F9: Firmado | G9: Firmado | H9: LUIS LANAS
A10: 8 | B10: 46195 | C10: PELUCHE-UCN-ROSA | D10: 1 | E10: =D10 * VLOOKUP(C10, CHOOSE({1,2}, Inventario!G:G, Inventario!E:E), 2, FALSE) -> 10085 | F10: Firmado | G10: Firmado | H10: CRISTINA MARAMBIO
A11: 9 | B11: 46195 | C11: PELUCHE-UCN-ROSA | D11: 1 | E11: =D11 * VLOOKUP(C11, CHOOSE({1,2}, Inventario!G:G, Inventario!E:E), 2, FALSE) -> 10085 | F11: Firmado | G11: Firmado | H11: ALEJANDRA VEGA
A12: 10 | B12: 46254 | C12: LAPIZ-COBRE-UNI | D12: 2 | E12: =D12 * VLOOKUP(C12, CHOOSE({1,2}, Inventario!G:G, Inventario!E:E), 2, FALSE) -> 30000 | F12: Pendiente | G12: Pendiente | H12: JOHANNA ROJAS
A13: 11 | B13: 46254 | C13: TOTE-BAG-UCN-UNI | D13: 6 | E13: =D13 * VLOOKUP(C13, CHOOSE({1,2}, Inventario!G:G, Inventario!E:E), 2, FALSE) -> 36000 | F13: Pendiente | G13: Pendiente | H13: JOHANNA ROJAS
A14: 12 | B14: 46269 | C14: PELUCHE-UCN-ROSA | D14: 1 | E14: =D14 * VLOOKUP(C14, CHOOSE({1,2}, Inventario!G:G, Inventario!E:E), 2, FALSE) -> 10085 | F14: Pendiente | G14: Pendiente | H14: CAROLINA SALINAS
... A18: 15 | B18: 46302 | C18: LLAVERO-UCENIN-UNI | D18: 3 | E18: =D18 * VLOOKUP(C18, CHOOSE({1,2}, Inventario!G:G, Inventario!E:E), 2, FALSE) -> 15000 | F18: Pendiente | G18: Pendiente | H18: MONICA CASTILLO
